<?xml version="1.0" ?>
<!-- =================================================================================== -->
<!-- |    This document was autogenerated by xacro from robotic_arm.xacro              | -->
<!-- |    EDITING THIS FILE BY HAND IS NOT RECOMMENDED                                 | -->
<!-- =================================================================================== -->
<robot name="robotic_arm">
  <material name="silver_default">
    <color rgba="0.700 0.700 0.700 1.000"/>
  </material>
  <material name="oak">
    <color rgba="0.7098 0.5882 0.4431 1.000"/>
  </material>
  <material name="pa_12_nylon_pa_603cf_with_eos_p_3d_printers">
    <color rgba="0.24705882352941178 0.24705882352941178 0.24705882352941178 1.0"/>
  </material>
  <material name="paint_enamel_glossy_blue">
    <color rgba="0.18823529411764706 0.23137254901960785 0.5882352941176471 1.0"/>
  </material>
  <material name="opaque160160160">
    <color rgba="0.6274509803921569 0.6274509803921569 0.6274509803921569 1.0"/>
  </material>
  <transmission name="base_waist_joint_tran">
    <type>transmission_interface/SimpleTransmission</type>
    <joint name="base_waist_joint">
      <hardwareInterface>hardware_interface/EffortJointInterface</hardwareInterface>
    </joint>
    <actuator name="base_waist_joint_actr">
      <hardwareInterface>hardware_interface/EffortJointInterface</hardwareInterface>
      <mechanicalReduction>1</mechanicalReduction>
    </actuator>
  </transmission>
  <transmission name="waist_link1_joint_tran">
    <type>transmission_interface/SimpleTransmission</type>
    <joint name="waist_link1_joint">
      <hardwareInterface>hardware_interface/EffortJointInterface</hardwareInterface>
    </joint>
    <actuator name="waist_link1_joint_actr">
      <hardwareInterface>hardware_interface/EffortJointInterface</hardwareInterface>
      <mechanicalReduction>1</mechanicalReduction>
    </actuator>
  </transmission>
  <transmission name="link1_link2_joint_tran">
    <type>transmission_interface/SimpleTransmission</type>
    <joint name="link1_link2_joint">
      <hardwareInterface>hardware_interface/EffortJointInterface</hardwareInterface>
    </joint>
    <actuator name="link1_link2_joint_actr">
      <hardwareInterface>hardware_interface/EffortJointInterface</hardwareInterface>
      <mechanicalReduction>1</mechanicalReduction>
    </actuator>
  </transmission>
  <transmission name="link2_gripperbase_joint_tran">
    <type>transmission_interface/SimpleTransmission</type>
    <joint name="link2_gripperbase_joint">
      <hardwareInterface>hardware_interface/EffortJointInterface</hardwareInterface>
    </joint>
    <actuator name="link2_gripperbase_joint_actr">
      <hardwareInterface>hardware_interface/EffortJointInterface</hardwareInterface>
      <mechanicalReduction>1</mechanicalReduction>
    </actuator>
  </transmission>
  <transmission name="left_gripper_joint_tran">
    <type>transmission_interface/SimpleTransmission</type>
    <joint name="left_gripper_joint">
      <hardwareInterface>hardware_interface/EffortJointInterface</hardwareInterface>
    </joint>
    <actuator name="left_gripper_joint_actr">
      <hardwareInterface>hardware_interface/EffortJointInterface</hardwareInterface>
      <mechanicalReduction>1</mechanicalReduction>
    </actuator>
  </transmission>
  <transmission name="right_gripper_joint_tran">
    <type>transmission_interface/SimpleTransmission</type>
    <joint name="right_gripper_joint">
      <hardwareInterface>hardware_interface/EffortJointInterface</hardwareInterface>
    </joint>
    <actuator name="right_gripper_joint_actr">
      <hardwareInterface>hardware_interface/EffortJointInterface</hardwareInterface>
      <mechanicalReduction>1</mechanicalReduction>
    </actuator>
  </transmission>
  <gazebo>
    <plugin filename="libgazebo_ros2_control.so" name="gazebo_ros2_control">
      <robot_param> robot_description</robot_param>
      <robot_param_node> robot_state_publisher</robot_param_node>
      <parameters>/home/newtonjeri/ai_based_sorting_robot_arm/install/robotic_arm_controllers/share/robotic_arm_controllers/config/robot_arm_controllers.yaml</parameters>
    </plugin>
  </gazebo>
  <gazebo reference="base_link">
    <material>Gazebo/Oak</material>
    <mu1>0.2</mu1>
    <mu2>0.2</mu2>
    <self_collide>true</self_collide>
    <gravity>true</gravity>
  </gazebo>
  <gazebo reference="base_v2_1">
    <material>Gazebo/FlatBlack</material>
    <mu1>0.2</mu1>
    <mu2>0.2</mu2>
    <self_collide>true</self_collide>
  </gazebo>
  <gazebo reference="waist_v6_1">
    <material>Gazebo/FlatBlack</material>
    <mu1>0.2</mu1>
    <mu2>0.2</mu2>
    <self_collide>true</self_collide>
  </gazebo>
  <gazebo reference="link_1_v5_1">
    <material>Gazebo/FlatBlack</material>
    <mu1>0.2</mu1>
    <mu2>0.2</mu2>
    <self_collide>true</self_collide>
  </gazebo>
  <gazebo reference="link_2a_v4_1">
    <material>Gazebo/FlatBlack</material>
    <mu1>0.2</mu1>
    <mu2>0.2</mu2>
    <self_collide>true</self_collide>
  </gazebo>
  <gazebo reference="link_2b_v4_1">
    <material>Gazebo/FlatBlack</material>
    <mu1>0.2</mu1>
    <mu2>0.2</mu2>
    <self_collide>true</self_collide>
  </gazebo>
  <gazebo reference="gripper_base_v8_1">
    <material>Gazebo/FlatBlack</material>
    <mu1>0.2</mu1>
    <mu2>0.2</mu2>
    <self_collide>true</self_collide>
  </gazebo>
  <gazebo reference="servomotormicro9g_v2_1">
    <material>Gazebo/Blue</material>
    <mu1>0.2</mu1>
    <mu2>0.2</mu2>
    <self_collide>true</self_collide>
  </gazebo>
  <gazebo reference="servomotormg996r_v2_2">
    <material>Gazebo/Blue</material>
    <mu1>0.2</mu1>
    <mu2>0.2</mu2>
    <self_collide>true</self_collide>
  </gazebo>
  <gazebo reference="servomotormicro9g_v2_2">
    <material>Gazebo/Blue</material>
    <mu1>0.2</mu1>
    <mu2>0.2</mu2>
    <self_collide>true</self_collide>
  </gazebo>
  <gazebo reference="servomotormg996r_v2_3">
    <material>Gazebo/Blue</material>
    <mu1>0.2</mu1>
    <mu2>0.2</mu2>
    <self_collide>true</self_collide>
  </gazebo>
  <gazebo reference="gripper_gear_1_v2_1">
    <material>GazeboGrey</material>
    <mu1>0.2</mu1>
    <mu2>0.2</mu2>
    <self_collide>true</self_collide>
  </gazebo>
  <gazebo reference="gripper_gear_2_v2_1">
    <material>GazeboGrey</material>
    <mu1>0.2</mu1>
    <mu2>0.2</mu2>
    <self_collide>true</self_collide>
  </gazebo>
  <gazebo reference="gripper_v3_1">
    <material>Gazebo/DarkGrey</material>
    <mu1>0.2</mu1>
    <mu2>0.2</mu2>
    <self_collide>true</self_collide>
  </gazebo>
  <gazebo reference="gripper_v3_2">
    <material>Gazebo/DarkGrey</material>
    <mu1>0.2</mu1>
    <mu2>0.2</mu2>
    <self_collide>true</self_collide>
  </gazebo>
  <gazebo reference="gripper_v3_3">
    <material>Gazebo/DarkGrey</material>
    <mu1>0.2</mu1>
    <mu2>0.2</mu2>
    <self_collide>true</self_collide>
  </gazebo>
  <gazebo reference="gripper_v3_4">
    <material>Gazebo/DarkGrey</material>
    <mu1>0.2</mu1>
    <mu2>0.2</mu2>
    <self_collide>true</self_collide>
  </gazebo>
  <ros2_control name="RoboticArmSystem" type="system">
    <hardware>
      <plugin>gazebo_ros2_control/GazeboSystem</plugin>
    </hardware>
    <!-- Interfaces -->
    <joint name="base_waist_joint">
      <command_interface name="position">
        <param name="min">-1.570795</param>
        <param name="max">1.570795</param>
      </command_interface>
      <state_interface name="position"/>
    </joint>
    <joint name="waist_link1_joint">
      <command_interface name="position">
        <param name="min">-1.570795</param>
        <param name="max">1.570795</param>
      </command_interface>
      <state_interface name="position"/>
    </joint>
    <joint name="link1_link2_joint">
      <command_interface name="position">
        <param name="min">0.0</param>
        <param name="max">3.14159</param>
      </command_interface>
      <state_interface name="position"/>
    </joint>
    <joint name="link2_gripperbase_joint">
      <command_interface name="position">
        <param name="min">-1.570795</param>
        <param name="max">1.570795</param>
      </command_interface>
      <state_interface name="position"/>
    </joint>
    <joint name="right_gripper_joint">
      <command_interface name="position">
        <param name="min">0.0</param>
        <param name="max">0.7854</param>
      </command_interface>
      <state_interface name="position"/>
    </joint>
    <joint name="left_gripper_joint">
      <param name="mimic">right_gripper_joint</param>
      <param name="multiplier">1</param>
      <command_interface name="position">
        <param name="min">-0.7854</param>
        <param name="max">0.0</param>
      </command_interface>
      <state_interface name="position"/>
    </joint>
  </ros2_control>
  <!-- Links -->
  <link name="world"/>
  <link name="base_link">
    <inertial>
      <origin rpy="0 0 0" xyz="4.1292719567255465e-17 -0.1275 0.0075"/>
      <mass value="2.5408670074548567"/>
      <inertia ixx="0.033061" ixy="-0.0" ixz="0.0" iyy="0.074955" iyz="0.0" izz="0.107921"/>
    </inertial>
    <visual>
      <origin rpy="0 0 0" xyz="0 0 0"/>
      <geometry>
        <mesh filename="package://robotic_arm_description/meshes/base_link.stl" scale="0.001 0.001 0.001"/>
      </geometry>
      <material name="oak"/>
    </visual>
    <collision>
      <origin rpy="0 0 0" xyz="0 0 0"/>
      <geometry>
        <mesh filename="package://robotic_arm_description/meshes/base_link.stl" scale="0.001 0.001 0.001"/>
      </geometry>
    </collision>
  </link>
  <link name="base_v2_1">
    <inertial>
      <origin rpy="0 0 0" xyz="3.307089559204383e-07 -0.06999939486232201 0.0513656205942673"/>
      <mass value="0.5102582987586253"/>
      <inertia ixx="0.001541" ixy="0.0" ixz="0.0" iyy="0.00162" iyz="0.0" izz="0.002267"/>
    </inertial>
    <visual>
      <origin rpy="0 0 0" xyz="-0.0 -0.07 -0.015"/>
      <geometry>
        <mesh filename="package://robotic_arm_description/meshes/base_v2_1.stl" scale="0.001 0.001 0.001"/>
      </geometry>
      <material name="pa_12_nylon_pa_603cf_with_eos_p_3d_printers"/>
    </visual>
    <collision>
      <origin rpy="0 0 0" xyz="-0.0 -0.07 -0.015"/>
      <geometry>
        <mesh filename="package://robotic_arm_description/meshes/base_v2_1.stl" scale="0.001 0.001 0.001"/>
      </geometry>
    </collision>
  </link>
  <link name="waist_v6_1">
    <inertial>
      <origin rpy="0 0 0" xyz="-0.007317934227206862 -0.0014787118544255873 0.019240916153628926"/>
      <mass value="0.08011233502112002"/>
      <inertia ixx="7.4e-05" ixy="-0.0" ixz="7e-06" iyy="5.5e-05" iyz="7e-06" izz="6.5e-05"/>
    </inertial>
    <visual>
      <origin rpy="0 0 0" xyz="-0.0 -0.0 -0.101"/>
      <geometry>
        <mesh filename="package://robotic_arm_description/meshes/waist_v6_1.stl" scale="0.001 0.001 0.001"/>
      </geometry>
      <material name="pa_12_nylon_pa_603cf_with_eos_p_3d_printers"/>
    </visual>
    <collision>
      <origin rpy="0 0 0" xyz="-0.0 -0.0 -0.101"/>
      <geometry>
        <mesh filename="package://robotic_arm_description/meshes/waist_v6_1.stl" scale="0.001 0.001 0.001"/>
      </geometry>
    </collision>
  </link>
  <link name="servomotormg996r_v2_2">
    <inertial>
      <origin rpy="0 0 0" xyz="-0.010054336562552477 0.020152986183403273 -0.013081986774102439"/>
      <mass value="0.2658706317147462"/>
      <inertia ixx="4.7e-05" ixy="2e-06" ixz="-2e-06" iyy="6.1e-05" iyz="1.5e-05" izz="6.1e-05"/>
    </inertial>
    <visual>
      <origin rpy="0 0 0" xyz="0.018 0.027168 -0.147467"/>
      <geometry>
        <mesh filename="package://robotic_arm_description/meshes/servomotormg996r_v2_2.stl" scale="0.001 0.001 0.001"/>
      </geometry>
      <material name="paint_enamel_glossy_blue"/>
    </visual>
    <collision>
      <origin rpy="0 0 0" xyz="0.018 0.027168 -0.147467"/>
      <geometry>
        <mesh filename="package://robotic_arm_description/meshes/servomotormg996r_v2_2.stl" scale="0.001 0.001 0.001"/>
      </geometry>
    </collision>
  </link>
  <link name="link_1_v5_1">
    <inertial>
      <origin rpy="0 0 0" xyz="0.0078177298783616 -2.360587438056394e-07 0.05999982401434481"/>
      <mass value="0.07112302510728019"/>
      <inertia ixx="0.000121" ixy="0.0" ixz="0.0" iyy="0.000116" iyz="-0.0" izz="1e-05"/>
    </inertial>
    <visual>
      <origin rpy="0 0 0" xyz="0.004 0.01391 -0.14128"/>
      <geometry>
        <mesh filename="package://robotic_arm_description/meshes/link_1_v5_1.stl" scale="0.001 0.001 0.001"/>
      </geometry>
      <material name="pa_12_nylon_pa_603cf_with_eos_p_3d_printers"/>
    </visual>
    <collision>
      <origin rpy="0 0 0" xyz="0.004 0.01391 -0.14128"/>
      <geometry>
        <mesh filename="package://robotic_arm_description/meshes/link_1_v5_1.stl" scale="0.001 0.001 0.001"/>
      </geometry>
    </collision>
  </link>
  <link name="link_2a_v4_1">
    <inertial>
      <origin rpy="0 0 0" xyz="-0.005701255904649023 -0.04181110897598475 -3.112432127394538e-05"/>
      <mass value="0.05167009815655824"/>
      <inertia ixx="6e-05" ixy="0.0" ixz="0.0" iyy="1e-05" iyz="-0.0" izz="5.6e-05"/>
    </inertial>
    <visual>
      <origin rpy="0 0 0" xyz="0.004 0.01391 -0.26128"/>
      <geometry>
        <mesh filename="package://robotic_arm_description/meshes/link_2a_v4_1.stl" scale="0.001 0.001 0.001"/>
      </geometry>
      <material name="pa_12_nylon_pa_603cf_with_eos_p_3d_printers"/>
    </visual>
    <collision>
      <origin rpy="0 0 0" xyz="0.004 0.01391 -0.26128"/>
      <geometry>
        <mesh filename="package://robotic_arm_description/meshes/link_2a_v4_1.stl" scale="0.001 0.001 0.001"/>
      </geometry>
    </collision>
  </link>
  <link name="link_2b_v4_1">
    <inertial>
      <origin rpy="0 0 0" xyz="-0.008613311986319927 -0.017710429447622786 -4.6451556616200484e-05"/>
      <mass value="0.017891783436233155"/>
      <inertia ixx="5e-06" ixy="1e-06" ixz="-0.0" iyy="3e-06" iyz="0.0" izz="4e-06"/>
    </inertial>
    <visual>
      <origin rpy="0 0 0" xyz="-0.004 0.10366 -0.26128"/>
      <geometry>
        <mesh filename="package://robotic_arm_description/meshes/link_2b_v4_1.stl" scale="0.001 0.001 0.001"/>
      </geometry>
      <material name="pa_12_nylon_pa_603cf_with_eos_p_3d_printers"/>
    </visual>
    <collision>
      <origin rpy="0 0 0" xyz="-0.004 0.10366 -0.26128"/>
      <geometry>
        <mesh filename="package://robotic_arm_description/meshes/link_2b_v4_1.stl" scale="0.001 0.001 0.001"/>
      </geometry>
    </collision>
  </link>
  <link name="servomotormg996r_v2_3">
    <inertial>
      <origin rpy="0 0 0" xyz="-0.010054336562552536 0.024498917400786264 0.005000000417687334"/>
      <mass value="0.2658706317147462"/>
      <inertia ixx="4.7e-05" ixy="-2e-06" ixz="-0.0" iyy="4.6e-05" iyz="-0.0" izz="7.5e-05"/>
    </inertial>
    <visual>
      <origin rpy="0 0 0" xyz="0.015 0.04866 -0.25628"/>
      <geometry>
        <mesh filename="package://robotic_arm_description/meshes/servomotormg996r_v2_3.stl" scale="0.001 0.001 0.001"/>
      </geometry>
      <material name="paint_enamel_glossy_blue"/>
    </visual>
    <collision>
      <origin rpy="0 0 0" xyz="0.015 0.04866 -0.25628"/>
      <geometry>
        <mesh filename="package://robotic_arm_description/meshes/servomotormg996r_v2_3.stl" scale="0.001 0.001 0.001"/>
      </geometry>
    </collision>
  </link>
  <link name="servomotormicro9g_v2_1">
    <inertial>
      <origin rpy="0 0 0" xyz="-0.005541210223247456 0.013371159759380774 -2.7755575615628914e-16"/>
      <mass value="0.05595068017526718"/>
      <inertia ixx="3e-06" ixy="0.0" ixz="0.0" iyy="4e-06" iyz="0.0" izz="6e-06"/>
    </inertial>
    <visual>
      <origin rpy="0 0 0" xyz="0.0065 0.14046 -0.26128"/>
      <geometry>
        <mesh filename="package://robotic_arm_description/meshes/servomotormicro9g_v2_1.stl" scale="0.001 0.001 0.001"/>
      </geometry>
      <material name="paint_enamel_glossy_blue"/>
    </visual>
    <collision>
      <origin rpy="0 0 0" xyz="0.0065 0.14046 -0.26128"/>
      <geometry>
        <mesh filename="package://robotic_arm_description/meshes/servomotormicro9g_v2_1.stl" scale="0.001 0.001 0.001"/>
      </geometry>
    </collision>
  </link>
  <link name="gripper_base_v8_1">
    <inertial>
      <origin rpy="0 0 0" xyz="0.011837914619012749 -0.02831046923426539 0.006706375607900994"/>
      <mass value="0.020668522851976897"/>
      <inertia ixx="9e-06" ixy="2e-06" ixz="-0.0" iyy="4e-06" iyz="1e-06" izz="1.1e-05"/>
    </inertial>
    <visual>
      <origin rpy="0 0 0" xyz="-0.004 0.13166 -0.26128"/>
      <geometry>
        <mesh filename="package://robotic_arm_description/meshes/gripper_base_v8_1.stl" scale="0.001 0.001 0.001"/>
      </geometry>
      <material name="pa_12_nylon_pa_603cf_with_eos_p_3d_printers"/>
    </visual>
    <collision>
      <origin rpy="0 0 0" xyz="-0.004 0.13166 -0.26128"/>
      <geometry>
        <mesh filename="package://robotic_arm_description/meshes/gripper_base_v8_1.stl" scale="0.001 0.001 0.001"/>
      </geometry>
    </collision>
  </link>
  <link name="gripper_gear_1_v2_1">
    <inertial>
      <origin rpy="0 0 0" xyz="-0.0005644997090396842 -0.005402189148709879 0.002000000134110169"/>
      <mass value="0.0029250313733063305"/>
      <inertia ixx="0.0" ixy="0.0" ixz="0.0" iyy="0.0" iyz="0.0" izz="1e-06"/>
    </inertial>
    <visual>
      <origin rpy="0 0 0" xyz="-0.0299 0.16966 -0.27528"/>
      <geometry>
        <mesh filename="package://robotic_arm_description/meshes/gripper_gear_1_v2_1.stl" scale="0.001 0.001 0.001"/>
      </geometry>
      <material name="opaque160160160"/>
    </visual>
    <collision>
      <origin rpy="0 0 0" xyz="-0.0299 0.16966 -0.27528"/>
      <geometry>
        <mesh filename="package://robotic_arm_description/meshes/gripper_gear_1_v2_1.stl" scale="0.001 0.001 0.001"/>
      </geometry>
    </collision>
  </link>
  <link name="gripper_v3_1">
    <inertial>
      <origin rpy="0 0 0" xyz="0.004099853901063728 -0.026539310482414202 0.0042500001341101434"/>
      <mass value="0.005742804742280986"/>
      <inertia ixx="2e-06" ixy="0.0" ixz="-0.0" iyy="0.0" iyz="0.0" izz="2e-06"/>
    </inertial>
    <visual>
      <origin rpy="0 0 0" xyz="-0.0299 0.20041 -0.27928"/>
      <geometry>
        <mesh filename="package://robotic_arm_description/meshes/gripper_v3_1.stl" scale="0.001 0.001 0.001"/>
      </geometry>
      <material name="pa_12_nylon_pa_603cf_with_eos_p_3d_printers"/>
    </visual>
    <collision>
      <origin rpy="0 0 0" xyz="-0.0299 0.20041 -0.27928"/>
      <geometry>
        <mesh filename="package://robotic_arm_description/meshes/gripper_v3_1.stl" scale="0.001 0.001 0.001"/>
      </geometry>
    </collision>
  </link>
  <link name="gripper_v3_2">
    <inertial>
      <origin rpy="0 0 0" xyz="0.004099853901063589 -0.026539310482414286 -0.004249999865889864"/>
      <mass value="0.005742804742280986"/>
      <inertia ixx="2e-06" ixy="0.0" ixz="0.0" iyy="0.0" iyz="0.0" izz="2e-06"/>
    </inertial>
    <visual>
      <origin rpy="0 0 0" xyz="-0.0299 0.20041 -0.27528"/>
      <geometry>
        <mesh filename="package://robotic_arm_description/meshes/gripper_v3_2.stl" scale="0.001 0.001 0.001"/>
      </geometry>
      <material name="pa_12_nylon_pa_603cf_with_eos_p_3d_printers"/>
    </visual>
    <collision>
      <origin rpy="0 0 0" xyz="-0.0299 0.20041 -0.27528"/>
      <geometry>
        <mesh filename="package://robotic_arm_description/meshes/gripper_v3_2.stl" scale="0.001 0.001 0.001"/>
      </geometry>
    </collision>
  </link>
  <link name="gripper_gear_2_v2_1">
    <inertial>
      <origin rpy="0 0 0" xyz="0.0005811920264956459 -0.005561932438407968 0.0020000001341103357"/>
      <mass value="0.0028410220441566826"/>
      <inertia ixx="0.0" ixy="-0.0" ixz="0.0" iyy="0.0" iyz="0.0" izz="0.0"/>
    </inertial>
    <visual>
      <origin rpy="0 0 0" xyz="-0.003 0.16966 -0.27528"/>
      <geometry>
        <mesh filename="package://robotic_arm_description/meshes/gripper_gear_2_v2_1.stl" scale="0.001 0.001 0.001"/>
      </geometry>
      <material name="opaque160160160"/>
    </visual>
    <collision>
      <origin rpy="0 0 0" xyz="-0.003 0.16966 -0.27528"/>
      <geometry>
        <mesh filename="package://robotic_arm_description/meshes/gripper_gear_2_v2_1.stl" scale="0.001 0.001 0.001"/>
      </geometry>
    </collision>
  </link>
  <link name="gripper_v3_3">
    <inertial>
      <origin rpy="0 0 0" xyz="-0.004099853901064021 -0.026539310482414313 -0.004249999865889698"/>
      <mass value="0.005742804742280986"/>
      <inertia ixx="2e-06" ixy="-0.0" ixz="-0.0" iyy="0.0" iyz="0.0" izz="2e-06"/>
    </inertial>
    <visual>
      <origin rpy="0 0 0" xyz="-0.003 0.20041 -0.27528"/>
      <geometry>
        <mesh filename="package://robotic_arm_description/meshes/gripper_v3_3.stl" scale="0.001 0.001 0.001"/>
      </geometry>
      <material name="pa_12_nylon_pa_603cf_with_eos_p_3d_printers"/>
    </visual>
    <collision>
      <origin rpy="0 0 0" xyz="-0.003 0.20041 -0.27528"/>
      <geometry>
        <mesh filename="package://robotic_arm_description/meshes/gripper_v3_3.stl" scale="0.001 0.001 0.001"/>
      </geometry>
    </collision>
  </link>
  <link name="gripper_v3_4">
    <inertial>
      <origin rpy="0 0 0" xyz="-0.004099853901064242 -0.026539310482414286 0.004250000134110088"/>
      <mass value="0.005742804742280986"/>
      <inertia ixx="2e-06" ixy="-0.0" ixz="-0.0" iyy="0.0" iyz="-0.0" izz="2e-06"/>
    </inertial>
    <visual>
      <origin rpy="0 0 0" xyz="-0.003 0.20041 -0.27928"/>
      <geometry>
        <mesh filename="package://robotic_arm_description/meshes/gripper_v3_4.stl" scale="0.001 0.001 0.001"/>
      </geometry>
      <material name="pa_12_nylon_pa_603cf_with_eos_p_3d_printers"/>
    </visual>
    <collision>
      <origin rpy="0 0 0" xyz="-0.003 0.20041 -0.27928"/>
      <geometry>
        <mesh filename="package://robotic_arm_description/meshes/gripper_v3_4.stl" scale="0.001 0.001 0.001"/>
      </geometry>
    </collision>
  </link>
  <!-- Joints -->
  <joint name="virtual_joint" type="fixed">
    <origin rpy="0.0 0.0 0.0" xyz="0.0 0.0 0.0"/>
    <parent link="world"/>
    <child link="base_link"/>
  </joint>
  <joint name="rigid_1" type="fixed">
    <origin rpy="0 0 0" xyz="0.0 0.07 0.015"/>
    <parent link="base_link"/>
    <child link="base_v2_1"/>
  </joint>
  <joint name="base_waist_joint" type="revolute">
    <origin rpy="0 0 0" xyz="0.0 -0.07 0.086"/>
    <parent link="base_v2_1"/>
    <child link="waist_v6_1"/>
    <axis xyz="0.0 0.0 1.0"/>
    <dynamics damping="10.0" friction="5.0"/>
    <limit effort="100" lower="-1.570796" upper="1.570796" velocity="100"/>
  </joint>
  <joint name="waist_link1_joint" type="revolute">
    <origin rpy="0 0 0" xyz="-0.004 -0.01391 0.04028"/>
    <parent link="waist_v6_1"/>
    <child link="link_1_v5_1"/>
    <axis xyz="1.0 0.0 0.0"/>
    <dynamics damping="10.0" friction="5.0"/>
    <limit effort="100" lower="-1.570796" upper="1.570796" velocity="100"/>
  </joint>
  <joint name="link1_link2_joint" type="revolute">
    <origin rpy="0 0 0" xyz="0.0 0.0 0.12"/>
    <parent link="link_1_v5_1"/>
    <child link="link_2a_v4_1"/>
    <axis xyz="-1.0 0.0 0.0"/>
    <dynamics damping="10.0" friction="5.0"/>
    <limit effort="100" lower="0.0" upper="3.141593" velocity="100"/>
  </joint>
  <joint name="link2_gripperbase_joint" type="revolute">
    <origin rpy="0 0 0" xyz="0.0 -0.028 0.0"/>
    <parent link="link_2b_v4_1"/>
    <child link="gripper_base_v8_1"/>
    <axis xyz="1.0 -0.0 0.0"/>
    <dynamics damping="10.0" friction="5.0"/>
    <limit effort="100" lower="-1.570796" upper="1.570796" velocity="100"/>
  </joint>
  <joint name="rigid_2" type="fixed">
    <origin rpy="0 0 0" xyz="-0.018 -0.027168 0.046467"/>
    <parent link="waist_v6_1"/>
    <child link="servomotormg996r_v2_2"/>
  </joint>
  <joint name="rigid_3" type="fixed">
    <origin rpy="0 0 0" xyz="0.008 -0.08975 0.0"/>
    <parent link="link_2a_v4_1"/>
    <child link="link_2b_v4_1"/>
  </joint>
  <joint name="rigid_4" type="fixed">
    <origin rpy="0 0 0" xyz="-0.011 -0.03475 -0.005"/>
    <parent link="link_2a_v4_1"/>
    <child link="servomotormg996r_v2_3"/>
  </joint>
  <joint name="rigid_5" type="fixed">
    <origin rpy="0 0 0" xyz="-0.0105 -0.0368 0.0"/>
    <parent link="link_2b_v4_1"/>
    <child link="servomotormicro9g_v2_1"/>
  </joint>
  <joint name="rigid_6" type="fixed">
    <origin rpy="0 0 0" xyz="0.0 -0.03075 0.004"/>
    <parent link="gripper_gear_1_v2_1"/>
    <child link="gripper_v3_1"/>
  </joint>
  <joint name="rigid_7" type="fixed">
    <origin rpy="0 0 0" xyz="0.0 -0.03075 0.0"/>
    <parent link="gripper_gear_1_v2_1"/>
    <child link="gripper_v3_2"/>
  </joint>
  <joint name="right_gripper_joint" type="revolute">
    <origin rpy="0 0 0" xyz="-0.001 -0.038 0.014"/>
    <parent link="gripper_base_v8_1"/>
    <child link="gripper_gear_2_v2_1"/>
    <axis xyz="0.0 0.0 -1.0"/>
    <dynamics damping="10.0" friction="5.0"/>
    <limit effort="100" lower="0.0" upper="0.7854" velocity="100"/>
  </joint>
  <joint name="left_gripper_joint" type="revolute">
    <origin rpy="0 0 0" xyz="0.0259 -0.038 0.014"/>
    <parent link="gripper_base_v8_1"/>
    <child link="gripper_gear_1_v2_1"/>
    <axis xyz="-0.0 -0.0 1.0"/>
    <dynamics damping="10.0" friction="5.0"/>
    <mimic joint="right_gripper_joint" multiplier="1.0"/>
    <limit effort="100" lower="0.0" upper="-0.7854" velocity="100"/>
  </joint>
  <joint name="rigid_8" type="fixed">
    <origin rpy="0 0 0" xyz="0.0 -0.03075 0.0"/>
    <parent link="gripper_gear_2_v2_1"/>
    <child link="gripper_v3_3"/>
  </joint>
  <joint name="rigid_9" type="fixed">
    <origin rpy="0 0 0" xyz="0.0 -0.03075 0.004"/>
    <parent link="gripper_gear_2_v2_1"/>
    <child link="gripper_v3_4"/>
  </joint>
</robot>
